#VRML_SIM R2023b utf8

EXTERNPROTO "https://raw.githubusercontent.com/cyberbotics/webots/R2023b/projects/objects/backgrounds/protos/TexturedBackground.proto"
EXTERNPROTO "https://raw.githubusercontent.com/cyberbotics/webots/R2023b/projects/objects/backgrounds/protos/TexturedBackgroundLight.proto"
EXTERNPROTO "https://raw.githubusercontent.com/cyberbotics/webots/R2023b/projects/objects/floors/protos/RectangleArena.proto"
EXTERNPROTO "https://raw.githubusercontent.com/cyberbotics/webots/R2023b/projects/objects/balls/protos/Ball.proto"

WorldInfo {
  basicTimeStep 4
}
Viewpoint {
  orientation 0.30011221173730473 0.4451230568645378 -0.843681293269984 1.4412323062842012
  position 0.041959943859796414 3.035316391340654 3.7422394587312526
}
TexturedBackground {
}
TexturedBackgroundLight {
}
RectangleArena {
  floorSize 6 2
  wallHeight 1
}
Solid {
  translation -2 0 0.6
  rotation 1 0 0 1.5708
  children [
    CadShape {
      url [
        "../cads/test.obj"
      ]
    }
  ]
  name "cad"
  model "floor"
  boundingObject Mesh {
    url [
      "../cads/test.obj"
    ]
  }
  locked TRUE
}
Robot {
  translation 2 0.45 1.57
  children [
    Solid {
      translation 0 0 -0.96
      children [
        HingeJoint {
          jointParameters HingeJointParameters {
            axis 0 0 1
          }
          device [
            RotationalMotor {
            }
          ]
          endPoint Solid {
            translation 0 0 1.05
            children [
              HingeJoint {
                jointParameters HingeJointParameters {
                  axis 0 1 0
                  anchor 0.000137119 -0.580963 1.00196
                  minStop -3.14
                  maxStop 3.14
                }
                device [
                  PositionSensor {
                    name "kij_position"
                  }
                  RotationalMotor {
                    name "kij_motor"
                    acceleration 1
                    maxVelocity 5
                    maxTorque 3000
                  }
                ]
                endPoint Solid {
                  translation 0.00013734221122431813 -0.5809631516717332 -1.0019952305039879
                  rotation -0.5775755000226759 0.5775447387767831 0.5769303393693325 2.094805953948294
                  children [
                    CadShape {
                      url [
                        "../cads/kij.obj"
                      ]
                      castShadows FALSE
                      isPickable FALSE
                    }
                  ]
                  name "kijcad"
                  boundingObject Mesh {
                    url [
                      "../cads/kij.obj"
                    ]
                  }
                  physics Physics {
                    density 3000
                  }
                }
              }
              Pose {
                translation 0 -0.23 0.96
                children [
                  Shape {
                    appearance Appearance {
                      material Material {
                        ambientIntensity 0.8
                        diffuseColor 0.417533 0.4094 0.294423
                        shininess 0.4
                      }
                    }
                    geometry Box {
                      size 0.2 0.6 0.1
                    }
                  }
                ]
              }
              Shape {
                appearance Appearance {
                  material Material {
                    ambientIntensity 0.8
                    diffuseColor 0.825223 0.837415 0.657832
                    shininess 0.4
                  }
                }
                geometry Cylinder {
                  radius 0.05
                }
              }
            ]
            name "robot_model"
          }
        }
        Shape {
          appearance Appearance {
            material Material {
              ambientIntensity 0.8
              diffuseColor 0.417533 0.4094 0.294423
              shininess 0.4
            }
          }
          geometry Box {
            size 0.4 0.4 0.1
          }
        }
      ]
      name "Baza"
    }
  ]
  controller "test"
}
Solid {
  translation 1.88 -0.26 0.64
  children [
    Shape {
      appearance Appearance {
      }
      geometry Box {
        size 0.3 0.1 0.1
      }
    }
  ]
  name "solid(1)"
}
Ball {
  translation 1.6466881492893841 0 0.704978418
  rotation 0 1 0 3.404645856653577e-13
  color 0.843137 0.843137 0.843137
  radius 0.11
  mass 0.2
}
