#VRML_SIM R2023b utf8

EXTERNPROTO "https://raw.githubusercontent.com/cyberbotics/webots/R2023b/projects/objects/backgrounds/protos/TexturedBackground.proto"
EXTERNPROTO "https://raw.githubusercontent.com/cyberbotics/webots/R2023b/projects/objects/backgrounds/protos/TexturedBackgroundLight.proto"
EXTERNPROTO "https://raw.githubusercontent.com/cyberbotics/webots/R2023b/projects/objects/floors/protos/RectangleArena.proto"
EXTERNPROTO "https://raw.githubusercontent.com/cyberbotics/webots/R2023b/projects/objects/balls/protos/Ball.proto"

WorldInfo {
  basicTimeStep 4
}
Viewpoint {
  orientation -0.024361312573397288 0.07698730777979237 0.9967344084010146 0.8882964521052295
  position 1.1025338613165487 -7.593346064515871 1.8285621075774325
}
TexturedBackground {
}
TexturedBackgroundLight {
}
RectangleArena {
  translation 0 -1.99 0
  floorSize 6 6
  wallHeight 1
}
Solid {
  translation -2 0 0.6
  rotation 1 0 0 1.5708
  children [
    CadShape {
      url [
        "../cads/cads/test2.obj"
      ]
    }
  ]
  name "cad"
  model "floor"
  boundingObject Mesh {
    url [
      "../cads/cads/test2.obj"
    ]
  }
  locked TRUE
}
DEF ROBOT Robot {
  translation 2.71 -4.31 1.57
  children [
    DEF BASE Solid {
      translation 0 0 -0.96
      children [
        DEF MODEL HingeJoint {
          jointParameters HingeJointParameters {
            axis 0 0 1
          }
          device [
            RotationalMotor {
            }
          ]
          endPoint DEF SOLID Solid {
            translation 0.01 0 1.05
            children [
              Solid {
                translation -1.32395e-06 -0.3 1.05
                rotation -1.40702e-06 2.72391e-07 1 -3.1415853071795863
                children [
                  Shape {
                    appearance PBRAppearance {
                    }
                    geometry Cylinder {
                      height 0.1
                      radius 0.05
                    }
                  }
                  Camera {
                  }
                ]
              }
              DEF DISPENSER Solid {
                translation -0.25 -0.31 1.01
                rotation 0 0 1 -1.5707953071795862
                children [
                  DEF sj0 SliderJoint {
                    jointParameters JointParameters {
                      position 0.3
                      axis 0 1 0
                    }
                    device [
                      LinearMotor {
                        name "ball top block 0"
                      }
                    ]
                    endPoint DEF bbs0 Solid {
                      translation 0 0.010000000000000009 0.42
                      children [
                        Shape {
                          appearance PBRAppearance {
                            metalness 0
                          }
                          geometry Box {
                            size 0.1 0.1 0.01
                          }
                        }
                      ]
                      name "solid(9)"
                      boundingObject DEF bb0 Box {
                        size 0.1 0.1 0.01
                      }
                    }
                  }
                  SliderJoint {
                    jointParameters JointParameters {
                      position 0.3
                      axis 0 1 0
                    }
                    device [
                      LinearMotor {
                        name "ball top block q"
                      }
                    ]
                    endPoint Solid {
                      translation 0 0.010000000000000009 0
                      children [
                        Shape {
                          appearance PBRAppearance {
                            metalness 0
                          }
                          geometry Box {
                            size 0.1 0.1 0.001
                          }
                        }
                      ]
                      name "solid(6)"
                      boundingObject Box {
                        size 0.1 0.1 0.01
                      }
                    }
                  }
                  DEF sj1 SliderJoint {
                    jointParameters JointParameters {
                      axis 0 1 0
                    }
                    device [
                      LinearMotor {
                        name "ball top block 1"
                      }
                    ]
                    endPoint DEF bbs1 Solid {
                      translation 0 0.04 0.72
                      children [
                        Shape {
                          appearance PBRAppearance {
                            metalness 0
                          }
                          geometry Box {
                            size 0.1 0.1 0.01
                          }
                        }
                      ]
                      name "solid(3)"
                      boundingObject DEF bb1 Box {
                        size 0.1 0.01 0.01
                      }
                    }
                  }
                  DEF sj2 SliderJoint {
                    jointParameters JointParameters {
                      axis 0 1 0
                    }
                    device [
                      LinearMotor {
                        name "ball top block 2"
                      }
                    ]
                    endPoint DEF bbs2 Solid {
                      translation 0 0.04 1
                      children [
                        Shape {
                          appearance PBRAppearance {
                            metalness 0
                          }
                          geometry Box {
                            size 0.1 0.1 0.01
                          }
                        }
                      ]
                      name "solid(4)"
                      boundingObject DEF bb2 Box {
                        size 0.1 0.01 0.01
                      }
                    }
                  }
                  Solid {
                    translation 0.1700319999999449 0.1499999999999857 0.07160790999996536
                    rotation -1.4517501094857412e-06 -0.9999999999987793 -5.774797753793547e-07 1.5707925009516284
                    children [
                      Shape {
                        appearance PBRAppearance {
                          metalness 0
                        }
                        geometry Box {
                          size 0.2 0.5 0.05
                        }
                      }
                    ]
                    name "solid(1)"
                    boundingObject Box {
                      size 0.2 0.5 0.05
                    }
                    physics Physics {
                    }
                  }
                  Solid {
                    translation -0.18003199999994557 0.14999999999996172 0.07160800999996564
                    rotation 5.791757346311752e-07 -0.9999999999987541 1.4683587444751589e-06 1.5707981103897106
                    children [
                      Shape {
                        appearance PBRAppearance {
                          metalness 0
                        }
                        geometry Box {
                          size 0.2 0.5 0.05
                        }
                      }
                    ]
                    name "solid(2)"
                    boundingObject Box {
                      size 0.2 0.5 0.05
                    }
                    physics Physics {
                    }
                  }
                  Solid {
                    translation 0.16015692426558115 0.049995417413648546 0.6361604488008172
                    rotation -0.5773392951725427 -0.5773427834481109 0.5773687285003055 2.094369943748204
                    children [
                      Shape {
                        appearance PBRAppearance {
                          metalness 0
                        }
                        geometry Box {
                          size 0.3 1 0.05
                        }
                      }
                    ]
                    name "solid(8)"
                    boundingObject Box {
                      size 0.3 1 0.05
                    }
                    physics Physics {
                    }
                  }
                  Solid {
                    translation -0.18011147933613358 0.050008083095564704 0.6361263071872574
                    rotation -0.5773560144564933 -0.5773531140190735 0.5773416789938105 2.0944075547179515
                    children [
                      Shape {
                        appearance PBRAppearance {
                          metalness 0
                        }
                        geometry Box {
                          size 0.3 1 0.05
                        }
                      }
                    ]
                    name "solid(5)"
                    boundingObject Box {
                      size 0.3 1 0.05
                    }
                    physics Physics {
                    }
                  }
                  Solid {
                    translation -0.010024642672813222 -0.12018038321383573 0.684498824646973
                    rotation 0.999999999998709 9.227719768521568e-07 -1.315389621074551e-06 1.5708368445694945
                    children [
                      Shape {
                        appearance PBRAppearance {
                          metalness 0
                        }
                        geometry Box {
                          size 0.4 1.5 0.05
                        }
                      }
                    ]
                    name "solid(10)"
                    boundingObject Box {
                      size 0.4 1.5 0.05
                    }
                    physics Physics {
                    }
                  }
                  Solid {
                    translation -0.010036652138167845 0.17011187635378588 0.8637921561003057
                    rotation 0.9999999999973126 8.986838573859404e-07 2.1371203403414957e-06 1.5707914789572834
                    children [
                      Shape {
                        appearance PBRAppearance {
                          metalness 0
                        }
                        geometry Box {
                          size 0.4 0.5 0.05
                        }
                      }
                    ]
                    name "solid(11)"
                    boundingObject Box {
                      size 0.4 0.5 0.05
                    }
                    physics Physics {
                    }
                  }
                  Solid {
                    translation -0.01003543716866595 0.17009428568768348 0.4037849742355797
                    rotation 0.9999999999980791 7.878140993251307e-07 1.7948352244236918e-06 1.5707931356700888
                    children [
                      Shape {
                        appearance PBRAppearance {
                          metalness 0
                        }
                        geometry Box {
                          size 0.4 0.5 0.05
                        }
                      }
                    ]
                    name "solid(7)"
                    boundingObject Box {
                      size 0.4 0.5 0.05
                    }
                    physics Physics {
                    }
                  }
                ]
                name "dispenser"
              }
              HingeJoint {
                jointParameters HingeJointParameters {
                  position -8.016340903903742e-05
                  axis 0 1 0
                  anchor 0.000137119 -0.580963 1.00196
                  minStop -3.14
                  maxStop 3.14
                }
                device [
                  Brake {
                    name "kij_brake"
                  }
                  PositionSensor {
                    name "kij_position"
                  }
                  RotationalMotor {
                    name "kij_motor"
                    acceleration 1
                    maxVelocity 5
                    maxTorque 3000
                  }
                ]
                endPoint Solid {
                  translation 0.0002979909176315967 -0.5809631516717332 -1.00199522404775
                  rotation -0.5776063409744057 0.5775293227534386 0.5769148951328205 2.0947596552187577
                  children [
                    CadShape {
                      url [
                        "../cads/kij.obj"
                      ]
                      castShadows FALSE
                      isPickable FALSE
                    }
                  ]
                  name "kijcad"
                  boundingObject Mesh {
                    url [
                      "../cads/kij.obj"
                    ]
                  }
                  physics Physics {
                    density 3000
                  }
                }
              }
              Pose {
                translation 0 -0.23 0.96
                children [
                  Shape {
                    appearance Appearance {
                      material Material {
                        ambientIntensity 0.8
                        diffuseColor 0.417533 0.4094 0.294423
                        shininess 0.4
                      }
                    }
                    geometry Box {
                      size 0.2 0.6 0.1
                    }
                  }
                ]
              }
              Shape {
                appearance Appearance {
                  material Material {
                    ambientIntensity 0.8
                    diffuseColor 0.825223 0.837415 0.657832
                    shininess 0.4
                  }
                }
                geometry Cylinder {
                  radius 0.05
                }
              }
            ]
            name "robot_model"
          }
        }
        Shape {
          appearance Appearance {
            material Material {
              ambientIntensity 0.8
              diffuseColor 0.417533 0.4094 0.294423
              shininess 0.4
            }
          }
          geometry Box {
            size 0.4 0.4 0.1
          }
        }
      ]
      name "Baza"
    }
  ]
  controller "auto_player"
}
Ball {
  translation -2.543956448042907 -4.634379379660783 0.10996076111670082
  rotation -0.0173036277005633 0.12961157449562336 0.9914138511364293 2.384988385232052
  name "ball(3)"
  color 0.843137 0 0
  radius 0.11
  mass 0.2
}
Ball {
  translation 2.505119172961227 -4.575234630919093 3.7849607630411675
  rotation 0.04434093639525167 -0.9905768507335783 -0.12958157334412412 1.0999034228039182
  name "ball(4)"
  color 0.843137 0 0
  radius 0.11
  mass 0.2
}
Ball {
  translation 2.505094691644095 -4.601367230613257 3.204960762713389
  rotation 0.16282784235513612 -0.9832842750867219 -0.0814808451180437 1.0846133003843499
  name "ball(1)"
  color 0.843137 0 0
  radius 0.11
  mass 0.2
}
Ball {
  translation 2.5051116098143877 -4.5748840416535925 3.5049607600004387
  rotation -0.17738551635515487 -0.9311575405847168 0.3185592773717892 2.4095060927858634
  name "ball(5)"
  color 0.843137 0 0
  radius 0.11
  mass 0.2
}
