#VRML_SIM R2023b utf8

EXTERNPROTO "https://raw.githubusercontent.com/cyberbotics/webots/R2023b/projects/objects/backgrounds/protos/TexturedBackground.proto"
EXTERNPROTO "https://raw.githubusercontent.com/cyberbotics/webots/R2023b/projects/objects/backgrounds/protos/TexturedBackgroundLight.proto"
EXTERNPROTO "https://raw.githubusercontent.com/cyberbotics/webots/R2023b/projects/objects/floors/protos/RectangleArena.proto"
EXTERNPROTO "https://raw.githubusercontent.com/cyberbotics/webots/R2023b/projects/objects/balls/protos/Ball.proto"

WorldInfo {
  basicTimeStep 16
}
Viewpoint {
  orientation -0.22574126710309841 -0.001308529540922009 0.9741864134123039 3.022216853997713
  position 5.389923632967628 -0.31444013171624 3.651675733888662
}
TexturedBackground {
}
TexturedBackgroundLight {
}
RectangleArena {
  floorSize 6 2
  wallHeight 1
}
Solid {
  translation -2 0 0.6
  rotation 1 0 0 1.5708
  children [
    CadShape {
      url [
        "../cads/test.obj"
      ]
    }
  ]
  name "cad"
  model "floor"
  boundingObject Mesh {
    url [
      "../cads/test.obj"
    ]
  }
  locked TRUE
}
Robot {
  translation 2 0.45 1.59
  children [
    Solid {
      translation 0 0 0.1
      children [
        HingeJoint {
          jointParameters HingeJointParameters {
            axis 0 1 0
            anchor 0.000137119 -0.580963 1.00196
          }
          device [
            RotationalMotor {
              name "kij_motor"
              acceleration 10
              maxTorque 3000
            }
          ]
          endPoint Solid {
            translation 0.00013734221122433722 -0.5809631516717332 -1.001995230503986
            rotation -0.5775755000226778 0.5775447387767815 0.5769303393693326 2.0948059539483044
            children [
              CadShape {
                url [
                  "../cads/kij.obj"
                ]
                castShadows FALSE
                isPickable FALSE
              }
            ]
            name "kijcad"
            boundingObject Mesh {
              url [
                "../cads/kij.obj"
              ]
            }
            physics Physics {
              density 3000
            }
          }
        }
        HingeJoint {
          jointParameters HingeJointParameters {
          }
          device [
            RotationalMotor {
            }
          ]
          endPoint Solid {
            translation 0 0 1.96
            children [
              Solid {
                translation 0 0 -3
                children [
                  Shape {
                    appearance Appearance {
                      material Material {
                        ambientIntensity 0.8
                        diffuseColor 0.417533 0.4094 0.294423
                        shininess 0.4
                      }
                    }
                    geometry Box {
                      size 0.4 0.4 0.1
                    }
                  }
                ]
                name "Baza"
              }
            ]
          }
        }
        Pose {
          translation 0 -0.23 0.96
          children [
            Shape {
              appearance Appearance {
                material Material {
                  ambientIntensity 0.8
                  diffuseColor 0.417533 0.4094 0.294423
                  shininess 0.4
                }
              }
              geometry Box {
                size 0.2 0.6 0.1
              }
            }
          ]
        }
        Shape {
          appearance Appearance {
            material Material {
              ambientIntensity 0.8
              diffuseColor 0.825223 0.837415 0.657832
              shininess 0.4
            }
          }
          geometry Cylinder {
            radius 0.05
          }
        }
      ]
      name "robot_model"
    }
  ]
  controller "test"
}
Solid {
  translation 1.88 -0.26 0.64
  children [
    Shape {
      appearance Appearance {
      }
      geometry Box {
        size 0.3 0.1 0.1
      }
    }
  ]
  name "solid(1)"
}
Ball {
  translation 1.6466881492893841 0 0.704978418
  rotation 0 1 0 3.404645856653577e-13
  color 0.843137 0.843137 0.843137
  radius 0.11
  mass 0.2
}
