#VRML_SIM R2023b utf8

EXTERNPROTO "https://raw.githubusercontent.com/cyberbotics/webots/R2023b/projects/objects/backgrounds/protos/TexturedBackground.proto"
EXTERNPROTO "https://raw.githubusercontent.com/cyberbotics/webots/R2023b/projects/objects/backgrounds/protos/TexturedBackgroundLight.proto"
EXTERNPROTO "https://raw.githubusercontent.com/cyberbotics/webots/R2023b/projects/objects/floors/protos/RectangleArena.proto"
EXTERNPROTO "https://raw.githubusercontent.com/cyberbotics/webots/R2023b/projects/objects/balls/protos/Ball.proto"

WorldInfo {
  basicTimeStep 4
}
Viewpoint {
  orientation 0 0 1 4.71238898038469
  position 2.66683249027328 2.376993951818164 0.9080493026509261
}
TexturedBackground {
}
TexturedBackgroundLight {
}
RectangleArena {
  floorSize 6 2
  wallHeight 1
}
Solid {
  translation -2 0 0.6
  rotation 1 0 0 1.5708
  children [
    CadShape {
      url [
        "../cads/test.obj"
      ]
    }
  ]
  name "cad"
  model "floor"
  boundingObject Mesh {
    url [
      "../cads/test.obj"
    ]
  }
  locked TRUE
}
Robot {
  translation 2 0.45 1.57
  children [
    Solid {
      translation 0 0 -0.96
      children [
        HingeJoint {
          jointParameters HingeJointParameters {
            axis 0 0 1
          }
          device [
            RotationalMotor {
            }
          ]
          endPoint Solid {
            translation 0 0 1.05
            children [
              Solid {
                translation -0.25 -0.31 1.01
                rotation 0 0 1 -1.5707953071795862
                children [
                  SliderJoint {
                    jointParameters JointParameters {
                      axis 0 1 0
                    }
                    device [
                      LinearMotor {
                        name "ball top block 0"
                      }
                    ]
                    endPoint Solid {
                      translation 0 0.04 0.48
                      children [
                        Shape {
                          appearance PBRAppearance {
                            metalness 0
                          }
                          geometry Box {
                            size 0.1 0.1 0.01
                          }
                        }
                      ]
                      name "solid(9)"
                      boundingObject Box {
                        size 0.1 0.1 0.01
                      }
                    }
                  }
                  SliderJoint {
                    jointParameters JointParameters {
                      axis 0 1 0
                    }
                    device [
                      LinearMotor {
                        name "ball top block 1"
                      }
                    ]
                    endPoint Solid {
                      translation 0 0.04 0.73
                      children [
                        Shape {
                          appearance PBRAppearance {
                            metalness 0
                          }
                          geometry Box {
                            size 0.1 0.1 0.01
                          }
                        }
                      ]
                      name "solid(3)"
                      boundingObject Box {
                        size 0.1 0.1 0.01
                      }
                    }
                  }
                  SliderJoint {
                    jointParameters JointParameters {
                      axis 0 1 0
                    }
                    device [
                      LinearMotor {
                        name "ball top block 1"
                      }
                    ]
                    endPoint Solid {
                      translation 0 0.04 1
                      children [
                        Shape {
                          appearance PBRAppearance {
                            metalness 0
                          }
                          geometry Box {
                            size 0.1 0.1 0.01
                          }
                        }
                      ]
                      name "solid(4)"
                      boundingObject Box {
                        size 0.1 0.1 0.01
                      }
                    }
                  }
                  Solid {
                    translation 0.17003200000000002 0.1499999999999999 0.07949733000000592
                    rotation -1.4517501666371512e-06 -0.9999999999987795 -5.774795795099199e-07 1.570792500951718
                    children [
                      Shape {
                        appearance PBRAppearance {
                          metalness 0
                        }
                        geometry Box {
                          size 0.2 0.5 0.05
                        }
                      }
                    ]
                    name "solid(1)"
                    boundingObject Box {
                      size 0.2 0.5 0.05
                    }
                    physics Physics {
                    }
                  }
                  Solid {
                    translation -0.18003200000000014 0.1499999999999999 0.0794974300000062
                    rotation 5.791757245826375e-07 -0.9999999999987541 1.468358719039798e-06 1.5707981103895554
                    children [
                      Shape {
                        appearance PBRAppearance {
                          metalness 0
                        }
                        geometry Box {
                          size 0.2 0.5 0.05
                        }
                      }
                    ]
                    name "solid(2)"
                    boundingObject Box {
                      size 0.2 0.5 0.05
                    }
                    physics Physics {
                    }
                  }
                  Solid {
                    translation 0.159971 0.05 0.659211
                    rotation -0.5773499358311838 -0.5773509358347605 0.5773499359023557 2.094395307114814
                    children [
                      Shape {
                        appearance PBRAppearance {
                          metalness 0
                        }
                        geometry Box {
                          size 0.3 1 0.05
                        }
                      }
                    ]
                    name "solid(8)"
                    boundingObject Box {
                      size 0.3 1 0.05
                    }
                    physics Physics {
                    }
                  }
                  Solid {
                    translation -0.180029 0.05 0.659211
                    rotation -0.5773499358311838 -0.5773509358347605 0.5773499359023557 2.094395307114814
                    children [
                      Shape {
                        appearance PBRAppearance {
                          metalness 0
                        }
                        geometry Box {
                          size 0.3 1 0.05
                        }
                      }
                    ]
                    name "solid(5)"
                    boundingObject Box {
                      size 0.3 1 0.05
                    }
                    physics Physics {
                    }
                  }
                  Solid {
                    translation -0.01003070000000017 -0.11999999999999988 0.7290968400000057
                    rotation 1 0 0 1.5708000000000002
                    children [
                      Shape {
                        appearance PBRAppearance {
                          metalness 0
                        }
                        geometry Box {
                          size 0.4 1.5 0.05
                        }
                      }
                    ]
                    name "solid(10)"
                    boundingObject Box {
                      size 0.4 1.5 0.05
                    }
                    physics Physics {
                    }
                  }
                  Solid {
                    translation -0.01003070000000017 0.16999999999999993 0.8793346600000085
                    rotation 1 0 0 1.5708000000000002
                    children [
                      Shape {
                        appearance PBRAppearance {
                          metalness 0
                        }
                        geometry Box {
                          size 0.4 0.5 0.05
                        }
                      }
                    ]
                    name "solid(11)"
                    boundingObject Box {
                      size 0.4 0.5 0.05
                    }
                    physics Physics {
                    }
                  }
                ]
                name "dispenser"
              }
              HingeJoint {
                jointParameters HingeJointParameters {
                  position 1.4199510868716695e-05
                  axis 0 1 0
                  anchor 0.000137119 -0.580963 1.00196
                  minStop -3.14
                  maxStop 3.14
                }
                device [
                  PositionSensor {
                    name "kij_position"
                  }
                  RotationalMotor {
                    name "kij_motor"
                    acceleration 1
                    maxVelocity 5
                    maxTorque 3000
                  }
                ]
                endPoint Solid {
                  translation 0.0001088918508904334 -0.5809631516717332 -1.0019952303052118
                  rotation -0.577570038191003 0.5775474687752309 0.5769330743642344 2.0948141534301943
                  children [
                    CadShape {
                      url [
                        "../cads/kij.obj"
                      ]
                      castShadows FALSE
                      isPickable FALSE
                    }
                  ]
                  name "kijcad"
                  boundingObject Mesh {
                    url [
                      "../cads/kij.obj"
                    ]
                  }
                  physics Physics {
                    density 3000
                  }
                }
              }
              Pose {
                translation 0 -0.23 0.96
                children [
                  Shape {
                    appearance Appearance {
                      material Material {
                        ambientIntensity 0.8
                        diffuseColor 0.417533 0.4094 0.294423
                        shininess 0.4
                      }
                    }
                    geometry Box {
                      size 0.2 0.6 0.1
                    }
                  }
                ]
              }
              Shape {
                appearance Appearance {
                  material Material {
                    ambientIntensity 0.8
                    diffuseColor 0.825223 0.837415 0.657832
                    shininess 0.4
                  }
                }
                geometry Cylinder {
                  radius 0.05
                }
              }
            ]
            name "robot_model"
          }
        }
        Shape {
          appearance Appearance {
            material Material {
              ambientIntensity 0.8
              diffuseColor 0.417533 0.4094 0.294423
              shininess 0.4
            }
          }
          geometry Box {
            size 0.4 0.4 0.1
          }
        }
      ]
      name "Baza"
    }
  ]
  controller "test"
}
Solid {
  translation 1.65 -0.26 0.64
  children [
    Shape {
      appearance Appearance {
      }
      geometry Box {
        size 0.3 0.1 0.1
      }
    }
  ]
  name "solid(1)"
  boundingObject Box {
    size 0.3 0.1 0.1
  }
}
Ball {
  translation 2.690754210711795 0.5338700001071875 1.4649607600000005
  rotation 1.7500752077157267e-07 0.9999999999927949 3.7920232448957563e-06 0.005901472124104952
  color 0.843137 0 0
  radius 0.11
  mass 0.2
}
Ball {
  translation 2.7049707539579875 0.5295042962857633 1.2149607627485948
  rotation 3.7130613614841013e-06 -0.9999999999869602 -3.5061299969276478e-06 1.0626853119660762
  name "ball(2)"
  color 0.843137 0 0
  radius 0.11
  mass 0.2
}
Ball {
  translation 1.6848499999999964 0.05467151776454989 0.7099609608204401
  name "ball(1)"
  color 0.843137 0 0
  radius 0.11
  mass 0.2
}
Ball {
  translation 1.75485 0.134672 3.26996
  name "ball(3)"
  color 0.843137 0 0
  radius 0.11
  mass 0.2
}
Ball {
  translation 1.75485 0.134672 3.98996
  name "ball(4)"
  color 0.843137 0 0
  radius 0.11
  mass 0.2
}
Ball {
  translation 1.75485 0.134672 3.53996
  name "ball(5)"
  color 0.843137 0 0
  radius 0.11
  mass 0.2
}
Robot {
  translation 2.68 0.5 0.62
  children [
    SliderJoint {
      jointParameters JointParameters {
        axis 0 1 0
      }
      device [
        LinearMotor {
          name "ball top block 0"
        }
      ]
      endPoint Solid {
        translation 0 0.04 0.48
        children [
          Shape {
            appearance PBRAppearance {
              metalness 0
            }
            geometry Box {
              size 0.1 0.1 0.01
            }
          }
        ]
        name "solid(9)"
        boundingObject Box {
          size 0.1 0.1 0.01
        }
      }
    }
    SliderJoint {
      jointParameters JointParameters {
        axis 0 1 0
      }
      device [
        LinearMotor {
          name "ball top block 1"
        }
      ]
      endPoint Solid {
        translation 0 0.04 0.73
        children [
          Shape {
            appearance PBRAppearance {
              metalness 0
            }
            geometry Box {
              size 0.1 0.1 0.01
            }
          }
        ]
        name "solid(3)"
        boundingObject Box {
          size 0.1 0.1 0.01
        }
      }
    }
    SliderJoint {
      jointParameters JointParameters {
        axis 0 1 0
      }
      device [
        LinearMotor {
          name "ball top block 1"
        }
      ]
      endPoint Solid {
        translation 0 0.04 1
        children [
          Shape {
            appearance PBRAppearance {
              metalness 0
            }
            geometry Box {
              size 0.1 0.1 0.01
            }
          }
        ]
        name "solid(4)"
        boundingObject Box {
          size 0.1 0.1 0.01
        }
      }
    }
    Solid {
      translation 0.17003199999999996 0.15000000000000002 0.07954638000000047
      rotation -1.4517501665026866e-06 -0.9999999999987793 -5.774795796680745e-07 1.5707925009517185
      children [
        Shape {
          appearance PBRAppearance {
            metalness 0
          }
          geometry Box {
            size 0.2 0.5 0.05
          }
        }
      ]
      name "solid(1)"
      boundingObject Box {
        size 0.2 0.5 0.05
      }
      physics Physics {
      }
    }
    Solid {
      translation -0.1800320000000002 0.15000000000000002 0.07954648000000042
      rotation 5.791757246119173e-07 -0.9999999999987542 1.468358719135669e-06 1.570798110389556
      children [
        Shape {
          appearance PBRAppearance {
            metalness 0
          }
          geometry Box {
            size 0.2 0.5 0.05
          }
        }
      ]
      name "solid(2)"
      boundingObject Box {
        size 0.2 0.5 0.05
      }
      physics Physics {
      }
    }
    Solid {
      translation -0.18002900000000066 0.04999999999999982 0.17939744400000046
      rotation 0.5773499358561375 0.5773509358560255 -0.577349935856137 -2.0943953071795853
      children [
        Shape {
          appearance PBRAppearance {
            metalness 0
          }
          geometry Box {
            size 0.3 1.9 0.05
          }
        }
      ]
      name "solid(7)"
      boundingObject Box {
        size 0.2 1.9 0.05
      }
      physics Physics {
      }
    }
    Solid {
      translation 0.15997100028427624 0.05000000000000071 0.17939744397251445
      rotation 0.5773499358311838 0.5773509358347605 -0.5773499359023557 -2.094395307114815
      children [
        Shape {
          appearance PBRAppearance {
            metalness 0
          }
          geometry Box {
            size 0.3 1.9 0.05
          }
        }
      ]
      name "solid(8)"
      boundingObject Box {
        size 0.2 1.9 0.05
      }
      physics Physics {
      }
    }
    Solid {
      translation -0.01003070000000017 -0.12 0.7293911400000005
      rotation 1 0 0 1.5708000000000002
      children [
        Shape {
          appearance PBRAppearance {
            metalness 0
          }
          geometry Box {
            size 0.4 1.5 0.05
          }
        }
      ]
      name "solid(10)"
      boundingObject Box {
        size 0.4 1.5 0.05
      }
      physics Physics {
      }
    }
    Solid {
      translation -0.01003070000000017 0.17000000000000004 0.8794327600000008
      rotation 1 0 0 1.5708000000000002
      children [
        Shape {
          appearance PBRAppearance {
            metalness 0
          }
          geometry Box {
            size 0.4 0.5 0.05
          }
        }
      ]
      name "solid(11)"
      boundingObject Box {
        size 0.4 0.5 0.05
      }
      physics Physics {
      }
    }
  ]
  name "caddie"
  controller "<none>"
}
