#VRML_SIM R2023b utf8

EXTERNPROTO "https://raw.githubusercontent.com/cyberbotics/webots/R2023b/projects/objects/backgrounds/protos/TexturedBackground.proto"
EXTERNPROTO "https://raw.githubusercontent.com/cyberbotics/webots/R2023b/projects/objects/backgrounds/protos/TexturedBackgroundLight.proto"
EXTERNPROTO "https://raw.githubusercontent.com/cyberbotics/webots/R2023b/projects/objects/floors/protos/RectangleArena.proto"
EXTERNPROTO "https://raw.githubusercontent.com/cyberbotics/webots/R2023b/projects/objects/balls/protos/Ball.proto"
EXTERNPROTO "https://raw.githubusercontent.com/cyberbotics/webots/R2023b/projects/objects/factory/containers/protos/CardboardBox.proto"

WorldInfo {
  basicTimeStep 4
}
Viewpoint {
  orientation -0.3292853437125761 0.22761487560841312 0.9163856343362533 2.0406904957768774
  position 4.823420791596439 -10.641397815050098 8.5043506654776
}
TexturedBackground {
}
TexturedBackgroundLight {
}
RectangleArena {
  translation 0 -1.99 0
  floorSize 6 6
  wallHeight 1
}
Solid {
  translation -2 0 0.6
  rotation 1 0 0 1.5708
  children [
    CadShape {
      url [
        "../cads/cads/test2.obj"
      ]
    }
  ]
  name "cad"
  model "floor"
  boundingObject Mesh {
    url [
      "../cads/cads/test2.obj"
    ]
  }
  locked TRUE
}
DEF ROBOT Robot {
  translation 2.71 -4.31 1.57
  children [
    DEF BASE Solid {
      translation 0 0 -0.96
      children [
        DEF MODEL HingeJoint {
          jointParameters HingeJointParameters {
            axis 0 0 1
          }
          device [
            RotationalMotor {
            }
          ]
          endPoint DEF SOLID Solid {
            translation 0.01 0 1.05
            children [
              Solid {
                translation -1.24427e-06 -0.33 1.1
                rotation -1.40702e-06 2.72391e-07 1 -3.1415853071795863
                children [
                  Shape {
                    appearance PBRAppearance {
                    }
                    geometry Cylinder {
                      height 0.1
                      radius 0.05
                    }
                  }
                  Camera {
                  }
                ]
              }
              DEF DISPENSER Solid {
                translation -0.25 -0.31 1.01
                rotation 0 0 1 -1.5707953071795862
                children [
                  DEF sj0 SliderJoint {
                    jointParameters JointParameters {
                      position 0.13
                      axis 0 1 0
                    }
                    device [
                      LinearMotor {
                        name "ball top block 0"
                      }
                    ]
                    endPoint DEF bbs0 Solid {
                      translation 0 -0.15999999999999998 0.42
                      children [
                        Shape {
                          appearance PBRAppearance {
                            metalness 0
                          }
                          geometry Box {
                            size 0.1 0.1 0.01
                          }
                        }
                      ]
                      name "solid(9)"
                      boundingObject DEF bb0 Box {
                        size 0.1 0.1 0.01
                      }
                    }
                  }
                  SliderJoint {
                    jointParameters JointParameters {
                      position 0.3
                      axis 0 1 0
                    }
                    device [
                      LinearMotor {
                        name "ball top block q"
                      }
                    ]
                    endPoint Solid {
                      translation 0 0.010000000000000009 0
                      children [
                        Shape {
                          appearance PBRAppearance {
                            metalness 0
                          }
                          geometry Box {
                            size 0.1 0.1 0.001
                          }
                        }
                      ]
                      name "solid(6)"
                      boundingObject Box {
                        size 0.1 0.1 0.01
                      }
                    }
                  }
                  DEF sj1 SliderJoint {
                    jointParameters JointParameters {
                      axis 0 1 0
                    }
                    device [
                      LinearMotor {
                        name "ball top block 1"
                      }
                    ]
                    endPoint DEF bbs1 Solid {
                      translation 0 0.04 0.64
                      children [
                        Shape {
                          appearance PBRAppearance {
                            metalness 0
                          }
                          geometry Box {
                            size 0.1 0.1 0.01
                          }
                        }
                      ]
                      name "solid(3)"
                      boundingObject DEF bb1 Box {
                        size 0.1 0.01 0.01
                      }
                    }
                  }
                  DEF sj2 SliderJoint {
                    jointParameters JointParameters {
                      axis 0 1 0
                    }
                    device [
                      LinearMotor {
                        name "ball top block 2"
                      }
                    ]
                    endPoint DEF bbs2 Solid {
                      translation 0 0.04 1
                      children [
                        Shape {
                          appearance PBRAppearance {
                            metalness 0
                          }
                          geometry Box {
                            size 0.1 0.1 0.01
                          }
                        }
                      ]
                      name "solid(4)"
                      boundingObject DEF bb2 Box {
                        size 0.1 0.01 0.01
                      }
                    }
                  }
                  Solid {
                    translation 0.17003199999994578 0.1499999999999857 0.07159809999996636
                    rotation -1.4517501094857412e-06 -0.9999999999987793 -5.774797753008499e-07 1.5707925009516284
                    children [
                      Shape {
                        appearance PBRAppearance {
                          metalness 0
                        }
                        geometry Box {
                          size 0.2 0.5 0.05
                        }
                      }
                    ]
                    name "solid(1)"
                    boundingObject Box {
                      size 0.2 0.5 0.05
                    }
                    physics Physics {
                    }
                  }
                  Solid {
                    translation -0.18003199999994468 0.14999999999996172 0.07159819999996664
                    rotation 5.791757346311752e-07 -0.9999999999987541 1.4683587444751589e-06 1.5707981103897106
                    children [
                      Shape {
                        appearance PBRAppearance {
                          metalness 0
                        }
                        geometry Box {
                          size 0.2 0.5 0.05
                        }
                      }
                    ]
                    name "solid(2)"
                    boundingObject Box {
                      size 0.2 0.5 0.05
                    }
                    physics Physics {
                    }
                  }
                  Solid {
                    translation 0.210157 0.0499952 0.636134
                    rotation -0.5773392951725427 -0.5773427834481109 0.5773687285003055 2.094369943748204
                    children [
                      Shape {
                        appearance PBRAppearance {
                          metalness 0
                        }
                        geometry Box {
                          size 0.3 1 0.05
                        }
                      }
                    ]
                    name "solid(8)"
                    boundingObject Box {
                      size 0.3 1 0.05
                    }
                    physics Physics {
                    }
                  }
                  Solid {
                    translation -0.180111479478402 0.05000808309556426 0.636096877187255
                    rotation -0.5773560144627536 -0.5773531140241103 0.5773416789825133 2.094407554733062
                    children [
                      Shape {
                        appearance PBRAppearance {
                          metalness 0
                        }
                        geometry Box {
                          size 0.3 1 0.05
                        }
                      }
                    ]
                    name "solid(5)"
                    boundingObject Box {
                      size 0.3 1 0.05
                    }
                    physics Physics {
                    }
                  }
                  Solid {
                    translation -0.010024642672813222 -0.12018038321383528 0.6844399646469737
                    rotation 0.999999999998709 9.227719769306598e-07 -1.315389620996048e-06 1.5708368445694945
                    children [
                      Shape {
                        appearance PBRAppearance {
                          metalness 0
                        }
                        geometry Box {
                          size 0.4 1.5 0.05
                        }
                      }
                    ]
                    name "solid(10)"
                    boundingObject Box {
                      size 0.4 1.5 0.05
                    }
                    physics Physics {
                    }
                  }
                  Solid {
                    translation -0.010036652138069257 0.1701118769444201 0.8637725361136948
                    rotation 0.9999999999973126 8.986738071555145e-07 2.137109800366764e-06 1.5707914788810207
                    children [
                      Shape {
                        appearance PBRAppearance {
                          metalness 0
                        }
                        geometry Box {
                          size 0.4 0.5 0.05
                        }
                      }
                    ]
                    name "solid(11)"
                    boundingObject Box {
                      size 0.4 0.5 0.05
                    }
                    physics Physics {
                    }
                  }
                  Solid {
                    translation -0.010035437168728123 0.1700942874030793 0.4037653546785678
                    rotation 0.999999999998079 7.878085473029783e-07 1.7948257874599296e-06 1.570793136092424
                    children [
                      Shape {
                        appearance PBRAppearance {
                          metalness 0
                        }
                        geometry Box {
                          size 0.4 0.5 0.05
                        }
                      }
                    ]
                    name "solid(7)"
                    boundingObject Box {
                      size 0.4 0.5 0.05
                    }
                    physics Physics {
                    }
                  }
                ]
                name "dispenser"
              }
              HingeJoint {
                jointParameters HingeJointParameters {
                  position -8.5194086300468e-05
                  axis 0 1 0
                  anchor 0.000137119 -0.580963 1.00196
                  minStop -3.14
                  maxStop 3.14
                }
                device [
                  Brake {
                    name "kij_brake"
                  }
                  PositionSensor {
                    name "kij_position"
                  }
                  RotationalMotor {
                    name "kij_motor"
                    acceleration 1
                    maxVelocity 5
                    maxTorque 3000
                  }
                ]
                endPoint Solid {
                  translation 0.00030807216960801123 -0.5809631516717332 -1.001995223211992
                  rotation -0.5776082763489055 0.5775283553043683 0.5769139259132836 2.094756749857119
                  children [
                    CadShape {
                      url [
                        "../cads/kij.obj"
                      ]
                      castShadows FALSE
                      isPickable FALSE
                    }
                  ]
                  name "kijcad"
                  boundingObject Mesh {
                    url [
                      "../cads/kij.obj"
                    ]
                  }
                  physics Physics {
                    density 3000
                  }
                }
              }
              Pose {
                translation 0 -0.23 0.96
                children [
                  Shape {
                    appearance Appearance {
                      material Material {
                        ambientIntensity 0.8
                        diffuseColor 0.417533 0.4094 0.294423
                        shininess 0.4
                      }
                    }
                    geometry Box {
                      size 0.2 0.6 0.1
                    }
                  }
                ]
              }
              Shape {
                appearance Appearance {
                  material Material {
                    ambientIntensity 0.8
                    diffuseColor 0.825223 0.837415 0.657832
                    shininess 0.4
                  }
                }
                geometry Cylinder {
                  radius 0.05
                }
              }
            ]
            name "robot_model"
          }
        }
        Shape {
          appearance Appearance {
            material Material {
              ambientIntensity 0.8
              diffuseColor 0.417533 0.4094 0.294423
              shininess 0.4
            }
          }
          geometry Box {
            size 0.4 0.4 0.1
          }
        }
      ]
      name "Baza"
    }
  ]
  controller "auto_player"
}
Ball {
  translation -2.543964212596036 -4.6343776741654095 0.10996076111670501
  rotation -0.0173461651396553 0.12960298221986974 0.991414231063214 2.3850511532804473
  name "ball(3)"
  color 0.843137 0 0
  radius 0.11
  mass 0.2
}
Ball {
  translation 2.49156 -4.60203 3.83496
  rotation 0 0 1 1.1012360085463195
  name "ball(4)"
  color 0.843137 0 0
  radius 0.11
  mass 0.2
}
Ball {
  translation 2.50342 -4.60129 2.86144
  rotation 0 0 1 0.631784049043989
  name "ball(1)"
  color 0.843137 0 0
  radius 0.11
  mass 0.2
}
Ball {
  translation 2.48428 -4.62211 3.48496
  rotation 0 0 -1 1.62411
  name "ball(5)"
  color 0 0.843137 0
  radius 0.11
  mass 0.2
}
CardboardBox {
  translation 2.13 -4.18 0.63
  size 0.1 0.6 0.1
}
CardboardBox {
  translation -2.8 -4.18 0.63
  rotation 0 0 1 -0.523595307179586
  name "cardboard box(2)"
  size 0.1 0.6 0.1
}
CardboardBox {
  translation -2.82614 -4.7147 0.63
  rotation 0 0 1 0.523602
  name "cardboard box(3)"
  size 0.1 0.6 0.1
}
CardboardBox {
  translation 2.1332 0.738567 0.63
  rotation -8.756919999640137e-06 -2.346409999903575e-06 0.9999999999589053 -0.523595307179586
  name "cardboard box(1)"
  size 0.1 0.6 0.1
}
