#VRML_SIM R2023b utf8

EXTERNPROTO "https://raw.githubusercontent.com/cyberbotics/webots/R2023b/projects/objects/backgrounds/protos/TexturedBackground.proto"
EXTERNPROTO "https://raw.githubusercontent.com/cyberbotics/webots/R2023b/projects/objects/backgrounds/protos/TexturedBackgroundLight.proto"
EXTERNPROTO "https://raw.githubusercontent.com/cyberbotics/webots/R2023b/projects/objects/floors/protos/RectangleArena.proto"
EXTERNPROTO "https://raw.githubusercontent.com/cyberbotics/webots/R2023b/projects/objects/balls/protos/Ball.proto"

WorldInfo {
  basicTimeStep 4
}
Viewpoint {
  orientation -0.3067171212870006 -0.009718757270954137 0.9517510983794679 3.2023512637997595
  position 10.882123623110814 -2.656891725986572 7.363475276240049
}
TexturedBackground {
}
TexturedBackgroundLight {
}
RectangleArena {
  floorSize 6 6
  wallHeight 1
}
Solid {
  translation -2 2 0.6
  rotation 1 0 0 1.5708
  children [
    CadShape {
      url [
        "../cads/test2.obj"
      ]
    }
  ]
  name "cad"
  model "floor"
  boundingObject Mesh {
    url [
      "../cads/test2.obj"
    ]
  }
  locked TRUE
}
Robot {
  translation 2 -2.06 1.57
  rotation 5.672099200659476e-09 -0.7886308888621998 -0.6148669133498864 -5.307179586466759e-06
  children [
    Solid {
      translation 0 0 -0.96
      children [
        HingeJoint {
          jointParameters HingeJointParameters {
            axis 0 0 1
          }
          device [
            RotationalMotor {
            }
          ]
          endPoint Solid {
            translation 0 0 1.05
            children [
              HingeJoint {
                jointParameters HingeJointParameters {
                  position 1.4198235029053579e-05
                  axis 0 1 0
                  anchor 0.000137119 -0.580963 1.00196
                  minStop -3.14
                  maxStop 3.14
                }
                device [
                  PositionSensor {
                    name "kij_position"
                  }
                  RotationalMotor {
                    name "kij_motor"
                    acceleration 1
                    maxVelocity 5
                    maxTorque 3000
                  }
                ]
                endPoint Solid {
                  translation 0.0001088944076162375 -0.5809631516717332 -1.0019952303052504
                  rotation -0.5775700386818364 0.5775474685298949 0.5769330741184562 2.094814152693397
                  children [
                    CadShape {
                      url [
                        "../cads/kij.obj"
                      ]
                      castShadows FALSE
                      isPickable FALSE
                    }
                  ]
                  name "kijcad"
                  boundingObject Mesh {
                    url [
                      "../cads/kij.obj"
                    ]
                  }
                  physics Physics {
                    density 3000
                  }
                }
              }
              Pose {
                translation 0 -0.23 0.96
                children [
                  Shape {
                    appearance Appearance {
                      material Material {
                        ambientIntensity 0.8
                        diffuseColor 0.417533 0.4094 0.294423
                        shininess 0.4
                      }
                    }
                    geometry Box {
                      size 0.2 0.6 0.1
                    }
                  }
                ]
              }
              Shape {
                appearance Appearance {
                  material Material {
                    ambientIntensity 0.8
                    diffuseColor 0.825223 0.837415 0.657832
                    shininess 0.4
                  }
                }
                geometry Cylinder {
                  radius 0.05
                }
              }
            ]
            name "robot_model"
          }
        }
        Shape {
          appearance Appearance {
            material Material {
              ambientIntensity 0.8
              diffuseColor 0.417533 0.4094 0.294423
              shininess 0.4
            }
          }
          geometry Box {
            size 0.4 0.4 0.1
          }
        }
      ]
      name "Baza"
    }
  ]
  controller "<none>"
}
Solid {
  translation 1.56 -2.78 0.64
  rotation 0 0 1 4.692820414042842e-06
  children [
    Shape {
      appearance Appearance {
      }
      geometry Box {
        size 0.3 0.1 0.1
      }
    }
  ]
  name "solid(1)"
  boundingObject Box {
    size 0.3 0.1 0.1
  }
}
Solid {
  translation 1.53 -2.13 0.65
  children [
    Shape {
      appearance Appearance {
      }
      geometry Box {
        size 0.3 0.1 0.1
      }
    }
  ]
  name "solid(2)"
  boundingObject Box {
    size 0.3 0.1 0.1
  }
}
Ball {
  translation 1.53005 -1.96049 1.48447
  color 0.843137 0 0
  radius 0.11
  mass 0.2
}
Ball {
  translation 1.55005 -1.95049 1.82447
  name "ball(3)"
  color 0.843137 0 0
  radius 0.11
  mass 0.2
}
Ball {
  translation 1.68485 -2.45489 0.709976
  name "ball(1)"
  color 0.843137 0 0
  radius 0.11
  mass 0.2
}
Robot {
  translation 1.54 -1.98 0.62
  children [
    SliderJoint {
      jointParameters JointParameters {
        axis 0 1 0
      }
      device [
        LinearMotor {
          name "ball push"
        }
      ]
      endPoint Solid {
        translation 0 0.22 0.17
        children [
          Shape {
            appearance PBRAppearance {
              metalness 0
            }
            geometry Box {
              size 0.1 0.1 0.2
            }
          }
        ]
        name "solid(3)"
        boundingObject Box {
          size 0.1 0.1 0.1
        }
      }
    }
    SliderJoint {
      jointParameters JointParameters {
        axis 0 1 0
      }
      device [
        LinearMotor {
          name "ball top block"
        }
      ]
      endPoint Solid {
        translation 0 0.04 0.48
        children [
          Shape {
            appearance PBRAppearance {
              metalness 0
            }
            geometry Box {
              size 0.1 0.1 0.01
            }
          }
        ]
        name "solid(9)"
        boundingObject Box {
          size 0.1 0.1 0.01
        }
      }
    }
    SliderJoint {
      jointParameters JointParameters {
        position -0.2
      }
      device [
        LinearMotor {
          name "ball block"
        }
      ]
      endPoint Solid {
        translation 0 -0.19 0.32
        children [
          Shape {
            appearance PBRAppearance {
              metalness 0
            }
            geometry Box {
              size 0.1 0.1 0.1
            }
          }
        ]
        name "solid(6)"
        boundingObject Box {
          size 0.1 0.1 0.1
        }
      }
    }
    Solid {
      translation -0.009999999999753761 1.8234669330041697e-10 -9.8100185312755e-05
      rotation 0.986451507842537 0.11627815234710986 0.1157273259084788 4.234468767860286e-11
      children [
        Shape {
          appearance PBRAppearance {
            metalness 0
          }
          geometry Box {
            size 0.2 0.5 0.05
          }
        }
      ]
      boundingObject Box {
        size 0.2 0.5 0.05
      }
      physics Physics {
      }
    }
    Solid {
      translation 0.1100324474419283 5.162356976340376e-07 0.07956604467969619
      rotation -1.4517501665026864e-06 -0.9999999999987793 -5.774795796680743e-07 1.5707925009517187
      children [
        Shape {
          appearance PBRAppearance {
            metalness 0
          }
          geometry Box {
            size 0.2 0.5 0.05
          }
        }
      ]
      name "solid(1)"
      boundingObject Box {
        size 0.2 0.5 0.05
      }
      physics Physics {
      }
    }
    Solid {
      translation -0.13003239719500392 4.669182872563127e-07 0.0795661255879726
      rotation 5.79175724611917e-07 -0.9999999999987541 1.4683587191356687e-06 1.5707981103895565
      children [
        Shape {
          appearance PBRAppearance {
            metalness 0
          }
          geometry Box {
            size 0.2 0.5 0.05
          }
        }
      ]
      name "solid(2)"
      boundingObject Box {
        size 0.2 0.5 0.05
      }
      physics Physics {
      }
    }
    Solid {
      translation -0.180029 0.05 0.179472
      rotation 0.5773499358561373 0.5773509358560259 -0.577349935856137 -2.0943953071795853
      children [
        Shape {
          appearance PBRAppearance {
            metalness 0
          }
          geometry Box {
            size 0.3 1.9 0.05
          }
        }
      ]
      name "solid(7)"
      boundingObject Box {
        size 0.2 1.9 0.05
      }
      physics Physics {
      }
    }
    Solid {
      translation 0.159971 0.05 0.179472
      rotation 0.5773499358561373 0.5773509358560259 -0.577349935856137 -2.0943953071795853
      children [
        Shape {
          appearance PBRAppearance {
            metalness 0
          }
          geometry Box {
            size 0.3 1.9 0.05
          }
        }
      ]
      name "solid(8)"
      boundingObject Box {
        size 0.2 1.9 0.05
      }
      physics Physics {
      }
    }
    Solid {
      translation -0.0100307 -0.12 0.879472
      rotation 1 0 0 1.5708
      children [
        Shape {
          appearance PBRAppearance {
            metalness 0
          }
          geometry Box {
            size 0.4 0.5 0.05
          }
        }
      ]
      name "solid(10)"
      boundingObject Box {
        size 0.4 0.5 0.05
      }
      physics Physics {
      }
    }
    Solid {
      translation -0.0100307 0.17 0.879472
      rotation 1 0 0 1.5708
      children [
        Shape {
          appearance PBRAppearance {
            metalness 0
          }
          geometry Box {
            size 0.4 0.5 0.05
          }
        }
      ]
      name "solid(11)"
      boundingObject Box {
        size 0.4 0.5 0.05
      }
      physics Physics {
      }
    }
    Solid {
      translation -0.130027640064448 0.4662720844435889 0.24919133233932167
      rotation 0.3574068002679716 -0.8628569680840474 -0.3574048569214128 1.7177755978263662
      children [
        Shape {
          appearance PBRAppearance {
            metalness 0
          }
          geometry Box {
            size 0.2 0.5 0.05
          }
        }
      ]
      name "solid(4)"
      boundingObject Box {
        size 0.2 0.5 0.05
      }
      physics Physics {
      }
    }
    Solid {
      translation 0.10997563304456826 0.4592010781620882 0.24210132780417304
      rotation 0.35740694289312297 -0.86285690082168 -0.3574048766821705 1.7177748994754962
      children [
        Shape {
          appearance PBRAppearance {
            metalness 0
          }
          geometry Box {
            size 0.2 0.5 0.05
          }
        }
      ]
      name "solid(5)"
      boundingObject Box {
        size 0.2 0.5 0.05
      }
      physics Physics {
      }
    }
  ]
  name "caddie"
  controller "caddie_controller"
}
