#VRML_SIM R2023b utf8

EXTERNPROTO "https://raw.githubusercontent.com/cyberbotics/webots/R2023b/projects/objects/backgrounds/protos/TexturedBackground.proto"
EXTERNPROTO "https://raw.githubusercontent.com/cyberbotics/webots/R2023b/projects/objects/backgrounds/protos/TexturedBackgroundLight.proto"
EXTERNPROTO "https://raw.githubusercontent.com/cyberbotics/webots/R2023b/projects/objects/floors/protos/RectangleArena.proto"
EXTERNPROTO "https://raw.githubusercontent.com/cyberbotics/webots/R2023b/projects/objects/balls/protos/Ball.proto"

WorldInfo {
}
Viewpoint {
  orientation -0.2497163166946132 -0.005121721612203698 0.96830549370754 3.0633404679522673
  position 7.290308141434561 -0.29788495534126425 3.644473124983796
}
TexturedBackground {
}
TexturedBackgroundLight {
}
RectangleArena {
  floorSize 6 2
  wallHeight 1
}
Solid {
  translation -2 0 0.6
  rotation 1 0 0 1.5708
  children [
    CadShape {
      url [
        "../cads/test.obj"
      ]
    }
  ]
  name "cad"
  model "floor"
  boundingObject Mesh {
    url [
      "../cads/test.obj"
    ]
  }
  locked TRUE
}
Robot {
  translation 2 0.45 1.59
  children [
    Solid {
      translation 0 0 0.1
      children [
        HingeJoint {
          jointParameters HingeJointParameters {
            axis 0 1 0
            anchor 0 0 1
          }
          device [
            RotationalMotor {
            }
          ]
          endPoint Solid {
            translation 9.213970336138799e-05 -0.5790285366177974 -1.0014228966135712
            rotation -0.5773879900139169 0.5773600575581499 0.577302756726606 2.0942487482215353
            children [
              CadShape {
                url [
                  "../cads/kij.obj"
                ]
                castShadows FALSE
                isPickable FALSE
              }
            ]
            name "kijcad"
            boundingObject Mesh {
              url [
                "../cads/kij.obj"
              ]
            }
            physics Physics {
            }
          }
        }
        HingeJoint {
          jointParameters HingeJointParameters {
          }
          device [
            RotationalMotor {
            }
          ]
          endPoint Solid {
            translation 0 0 1.96
            children [
              Solid {
                translation 0 0 -3
                children [
                  Shape {
                    appearance Appearance {
                      material Material {
                        ambientIntensity 0.8
                        diffuseColor 0.417533 0.4094 0.294423
                        shininess 0.4
                      }
                    }
                    geometry Box {
                      size 0.4 0.4 0.1
                    }
                  }
                ]
                name "Baza"
              }
            ]
          }
        }
        Pose {
          translation 0 -0.26 0.96
          children [
            Shape {
              appearance Appearance {
                material Material {
                  ambientIntensity 0.8
                  diffuseColor 0.417533 0.4094 0.294423
                  shininess 0.4
                }
              }
              geometry Box {
                size 0.2 0.7 0.1
              }
            }
          ]
        }
        Shape {
          appearance Appearance {
            material Material {
              ambientIntensity 0.8
              diffuseColor 0.825223 0.837415 0.657832
              shininess 0.4
            }
          }
          geometry Cylinder {
            radius 0.05
          }
        }
      ]
      name "robot_model"
    }
  ]
}
Solid {
  translation 1.88 -0.26 0.64
  children [
    Shape {
      appearance Appearance {
      }
      geometry Box {
        size 0.3 0.1 0.1
      }
    }
  ]
  name "solid(1)"
}
Ball {
  translation 1.6466881492893841 0 0.704978418
  rotation 0 1 0 3.404645856653577e-13
  color 0.843137 0.843137 0.843137
  radius 0.11
  mass 0.2
}
