#VRML_SIM R2023b utf8

EXTERNPROTO "https://raw.githubusercontent.com/cyberbotics/webots/R2023b/projects/objects/backgrounds/protos/TexturedBackground.proto"
EXTERNPROTO "https://raw.githubusercontent.com/cyberbotics/webots/R2023b/projects/objects/backgrounds/protos/TexturedBackgroundLight.proto"
EXTERNPROTO "https://raw.githubusercontent.com/cyberbotics/webots/R2023b/projects/objects/floors/protos/RectangleArena.proto"
EXTERNPROTO "https://raw.githubusercontent.com/cyberbotics/webots/R2023b/projects/objects/floors/protos/Floor.proto"
EXTERNPROTO "https://raw.githubusercontent.com/cyberbotics/webots/R2023b/projects/objects/balls/protos/PingPongBall.proto"

WorldInfo {
}
Viewpoint {
  orientation -0.1785822298831988 0.8755595205532931 0.4488918724352578 0.633804587750619
  position 1.2010104581550802 0.43829270073451265 0.8948059512389915
}
TexturedBackground {
}
TexturedBackgroundLight {
}
RectangleArena {
  floorSize 6 2
  wallHeight 1
}
Solid {
  translation -2 0 0.6
  rotation 1 0 0 1.5708
  children [
    CadShape {
      url [
        "../cads/test.obj"
      ]
    }
  ]
}
Robot {
  translation 2 0.45 1.59
  children [
    Solid {
      translation 0 0 0.1
      children [
        HingeJoint {
          jointParameters HingeJointParameters {
          }
          device [
            RotationalMotor {
            }
          ]
          endPoint Solid {
            children [
              Pose {
                translation 2.0134e-06 -0.6 -1
                rotation -0.577349935856137 0.577349935856137 0.5773509358560258 2.09439
                children [
                  CadShape {
                    url [
                      "../cads/kij.obj"
                    ]
                  }
                ]
              }
            ]
            name "Kij"
          }
        }
        HingeJoint {
          jointParameters HingeJointParameters {
          }
          device [
            RotationalMotor {
            }
          ]
          endPoint Solid {
            translation 0 0 1.96
            children [
              Solid {
                translation 0 0 -3
                children [
                  Shape {
                    appearance Appearance {
                      material Material {
                        ambientIntensity 0.8
                        diffuseColor 0.417533 0.4094 0.294423
                        shininess 0.4
                      }
                    }
                    geometry Box {
                      size 0.4 0.4 0.1
                    }
                  }
                ]
                name "Baza"
              }
            ]
          }
        }
        Pose {
          translation 0 -0.26 0.96
          children [
            Shape {
              appearance Appearance {
                material Material {
                  ambientIntensity 0.8
                  diffuseColor 0.417533 0.4094 0.294423
                  shininess 0.4
                }
              }
              geometry Box {
                size 0.2 0.7 0.1
              }
            }
          ]
        }
        Shape {
          appearance Appearance {
            material Material {
              ambientIntensity 0.8
              diffuseColor 0.825223 0.837415 0.657832
              shininess 0.4
            }
          }
          geometry Cylinder {
            radius 0.05
          }
        }
      ]
      name "robot_model"
    }
  ]
}
Solid {
  translation 1.88 -0.26 0.64
  children [
    Shape {
      appearance Appearance {
      }
      geometry Box {
        size 0.3 0.1 0.1
      }
    }
  ]
  name "solid(1)"
}
Floor {
  translation 0.42 0 0.595
  size 4.3 2
}
Floor {
  translation -2.65 0 0.595
  name "floor(1)"
  size 0.73 2
}
Floor {
  translation -2.01 0.66 0.595
  name "floor(2)"
  size 0.555 0.75
}
Floor {
  translation -2.01 -0.67 0.595
  name "floor(3)"
  size 0.555 0.75
}
PingPongBall {
  hidden linearVelocity_0 0.0007359993310963311 2.8739305356170957e-06 1.455187902412679e-15
  hidden angularVelocity_0 -0.00014344812501241588 0.03673635209609933 -9.780666417500875e-05
  translation 1.605493063947223 0.6018574560523238 0.614998895446182
  rotation 0.9864164473442959 0.0009877924073904215 -0.16426081904951653 3.1231753842348478
}
